Workbook

Sheet 1. Add data
A1: Instruktion
A2: 1. Export data from MultiSizer 3.2 software to XLS files (max 20 files in one opreation)
A3: 2. The exportfile generated in MultiSizer is open by Excel - indicate comma delimited - copy the dat from this file to the present fil, starting from row 11
A4: 3. Blind samples from coolumn C - sample A1 from column H osv.
A9: Channel number | B9: Diameter | C9: Blind | D9: =C9 -> Blind | E9: A1 | F9: B1 | G9: C1 | H9: D1 | I9: A2 | J9: B2 | K9: C2 | L9: D2 | M9: A3 | N9: B3 | O9: C3 | P9: D3 | Q9: A4 | R9: B4 | S9: C4 | T9: D4 | U9: A5 | V9: B5 | W9: C5 | X9: D5 | Y9: A6 | Z9: B6 | AA9: C6 | AB9: D6
E15: MM exp1 48_1A_04.#m4 | F15: MM exp1 48_1B_05.#m4 | G15: MM exp1 48_1C_06.#m4 | H15: MM exp1 48_1D_07.#m4 | I15: MM exp1 48_2A_08.#m4 | J15: MM exp1 48_2B_09.#m4 | K15: MM Exp1 48_2C_12.#m4 | L15: MM Exp1 48_2D_13.#m4 | M15: MM Exp1 48_3A_14.#m4 | N15: MM Exp1 48_3B_15.#m4 | O15: MM Exp1 48_3C_16.#m4 | P15: MM Exp1 48_3D_17.#m4 | Q15: MM Exp1 48_4A_18.#m4 | R15: MM Exp1 48_4B_19.#m4 | S15: MM Exp1 48_4C_20.#m4 | T15: MM Exp1 48_4D 2_22.#m4 | U15: MM Exp1 48_5A_23.#m4 | V15: MM Exp1 48_5B_24.#m4 | W15: MM Exp1 48_5C_25.#m4 | X15: MM Exp1 48_5D_26.#m4 | Y15: MM Exp1 48_6A_27.#m4 | Z15: MM Exp1 48_6B_28.#m4 | AA15: MM Exp1 48_6C_29.#m4 | AB15: MM Exp1 48_6D_30.#m4
B16: Bin Diameter (Center) | E16: Diff. | F16: Diff. | G16: Diff. | H16: Diff. | I16: Diff. | J16: Diff. | K16: Diff. | L16: Diff. | M16: Diff. | N16: Diff. | O16: Diff. | P16: Diff. | Q16: Diff. | R16: Diff. | S16: Diff. | T16: Diff. | U16: Diff. | V16: Diff. | W16: Diff. | X16: Diff. | Y16: Diff. | Z16: Diff. | AA16: Diff. | AB16: Diff.
B17: um | E17: Number | F17: Number | G17: Number | H17: Number | I17: Number | J17: Number | K17: Number | L17: Number | M17: Number | N17: Number | O17: Number | P17: Number | Q17: Number | R17: Number | S17: Number | T17: Number | U17: Number | V17: Number | W17: Number | X17: Number | Y17: Number | Z17: Number | AA17: Number | AB17: Number
A18: 1 | B18: 9.039 | E18: 9 | F18: 14 | G18: 13 | H18: 7 | I18: 6 | J18: 13 | K18: 11 | L18: 9 | M18: 12 | N18: 15 | O18: 10 | P18: 8 | Q18: 12 | R18: 8 | S18: 3 | T18: 8 | U18: 7 | V18: 13 | W18: 11 | X18: 6 | Y18: 6 | Z18: 2 | AA18: 6 | AB18: 7
A19: 2 | B19: 9.116 | E19: 19 | F19: 5 | G19: 9 | H19: 16 | I19: 10 | J19: 7 | K19: 8 | L19: 6 | M19: 9 | N19: 10 | O19: 11 | P19: 5 | Q19: 11 | R19: 6 | S19: 6 | T19: 8 | U19: 7 | V19: 6 | W19: 11 | X19: 15 | Y19: 4 | Z19: 5 | AA19: 5 | AB19: 6
A20: 3 | B20: 9.194 | E20: 11 | F20: 10 | G20: 11 | H20: 17 | I20: 6 | J20: 4 | K20: 7 | L20: 8 | M20: 9 | N20: 9 | O20: 1 | P20: 13 | Q20: 14 | R20: 9 | S20: 12 | T20: 9 | U20: 9 | V20: 5 | W20: 7 | X20: 12 | Y20: 7 | Z20: 3 | AA20: 1 | AB20: 6
A21: 4 | B21: 9.271 | E21: 12 | F21: 5 | G21: 11 | H21: 8 | I21: 8 | J21: 7 | K21: 8 | L21: 11 | M21: 7 | N21: 12 | O21: 12 | P21: 9 | Q21: 6 | R21: 9 | S21: 4 | T21: 6 | U21: 5 | V21: 6 | W21: 8 | X21: 5 | Y21: 5 | Z21: 8 | AA21: 4 | AB21: 11
A22: 5 | B22: 9.349 | E22: 13 | F22: 6 | G22: 12 | H22: 3 | I22: 7 | J22: 8 | K22: 6 | L22: 10 | M22: 5 | N22: 10 | O22: 11 | P22: 8 | Q22: 12 | R22: 6 | S22: 6 | T22: 10 | U22: 15 | V22: 8 | W22: 10 | X22: 4 | Y22: 5 | Z22: 4 | AA22: 8 | AB22: 10
A23: 6 | B23: 9.426 | E23: 8 | F23: 9 | G23: 7 | H23: 6 | I23: 2 | J23: 9 | K23: 4 | L23: 9 | M23: 9 | N23: 6 | O23: 11 | P23: 6 | Q23: 9 | R23: 5 | S23: 9 | T23: 7 | U23: 4 | V23: 4 | W23: 3 | X23: 12 | Y23: 6 | Z23: 3 | AA23: 5 | AB23: 8
A24: 7 | B24: 9.504 | E24: 4 | F24: 12 | G24: 5 | H24: 16 | I24: 6 | J24: 9 | K24: 9 | L24: 10 | M24: 6 | N24: 3 | O24: 13 | P24: 9 | Q24: 6 | R24: 4 | S24: 7 | T24: 7 | U24: 5 | V24: 8 | W24: 7 | X24: 19 | Y24: 5 | Z24: 6 | AA24: 7 | AB24: 7
A25: 8 | B25: 9.581 | E25: 9 | F25: 8 | G25: 11 | H25: 10 | I25: 11 | J25: 6 | K25: 4 | L25: 6 | M25: 11 | N25: 10 | O25: 4 | P25: 8 | Q25: 7 | R25: 6 | S25: 3 | T25: 9 | U25: 8 | V25: 7 | W25: 5 | X25: 8 | Y25: 5 | Z25: 5 | AA25: 5 | AB25: 9
A26: 9 | B26: 9.659 | E26: 7 | F26: 6 | G26: 9 | H26: 14 | I26: 4 | J26: 5 | K26: 7 | L26: 0 | M26: 5 | N26: 2 | O26: 7 | P26: 4 | Q26: 5 | R26: 9 | S26: 6 | T26: 5 | U26: 10 | V26: 10 | W26: 4 | X26: 8 | Y26: 3 | Z26: 3 | AA26: 0 | AB26: 3
A27: 10 | B27: 9.736 | E27: 3 | F27: 8 | G27: 7 | H27: 11 | I27: 10 | J27: 4 | K27: 5 | L27: 9 | M27: 6 | N27: 7 | O27: 4 | P27: 5 | Q27: 4 | R27: 9 | S27: 7 | T27: 4 | U27: 5 | V27: 5 | W27: 5 | X27: 8 | Y27: 8 | Z27: 5 | AA27: 4 | AB27: 5
A28: 11 | B28: 9.814 | E28: 6 | F28: 2 | G28: 4 | H28: 10 | I28: 5 | J28: 6 | K28: 4 | L28: 3 | M28: 6 | N28: 5 | O28: 4 | P28: 9 | Q28: 3 | R28: 9 | S28: 7 | T28: 6 | U28: 2 | V28: 6 | W28: 5 | X28: 7 | Y28: 1 | Z28: 5 | AA28: 6 | AB28: 4
A29: 12 | B29: 9.891 | E29: 5 | F29: 8 | G29: 5 | H29: 9 | I29: 5 | J29: 7 | K29: 8 | L29: 10 | M29: 2 | N29: 8 | O29: 12 | P29: 4 | Q29: 6 | R29: 6 | S29: 3 | T29: 6 | U29: 7 | V29: 3 | W29: 7 | X29: 8 | Y29: 6 | Z29: 2 | AA29: 2 | AB29: 7
... A272: 255 | B272: 28.72 | E272: 1 | F272: 0 | G272: 0 | H272: 1 | I272: 0 | J272: 2 | K272: 0 | L272: 0 | M272: 0 | N272: 1 | O272: 1 | P272: 1 | Q272: 0 | R272: 1 | S272: 1 | T272: 0 | U272: 3 | V272: 2 | W272: 0 | X272: 0 | Y272: 0 | Z272: 2 | AA272: 3 | AB272: 2
A273: =A272+1 -> 256 | B273: 28.8 | E273: 0 | F273: 0 | G273: 1 | H273: 3 | I273: 0 | J273: 0 | K273: 0 | L273: 1 | M273: 2 | N273: 0 | O273: 2 | P273: 2 | Q273: 3 | R273: 0 | S273: 0 | T273: 1 | U273: 1 | V273: 2 | W273: 1 | X273: 2 | Y273: 1 | Z273: 3 | AA273: 2 | AB273: 0
A274: =A273+1 -> 257 | B274: 28.88 | E274: 0 | F274: 0 | G274: 1 | H274: 2 | I274: 1 | J274: 0 | K274: 0 | L274: 0 | M274: 1 | N274: 1 | O274: 1 | P274: 0 | Q274: 1 | R274: 0 | S274: 2 | T274: 2 | U274: 0 | V274: 0 | W274: 1 | X274: 2 | Y274: 1 | Z274: 0 | AA274: 0 | AB274: 2
A275: =A274+1 -> 258 | B275: 28.96 | E275: 0 | F275: 0 | G275: 1 | H275: 1 | I275: 1 | J275: 0 | K275: 1 | L275: 0 | M275: 1 | N275: 0 | O275: 1 | P275: 0 | Q275: 1 | R275: 0 | S275: 2 | T275: 0 | U275: 3 | V275: 2 | W275: 2 | X275: 2 | Y275: 2 | Z275: 1 | AA275: 1 | AB275: 0
A276: =A275+1 -> 259 | B276: 29.03 | E276: 2 | F276: 0 | G276: 1 | H276: 1 | I276: 1 | J276: 0 | K276: 0 | L276: 0 | M276: 1 | N276: 1 | O276: 1 | P276: 0 | Q276: 2 | R276: 0 | S276: 2 | T276: 0 | U276: 2 | V276: 5 | W276: 1 | X276: 0 | Y276: 3 | Z276: 0 | AA276: 2 | AB276: 0
A277: =A276+1 -> 260 | B277: 29.11 | E277: 2 | F277: 0 | G277: 1 | H277: 2 | I277: 0 | J277: 1 | K277: 0 | L277: 1 | M277: 1 | N277: 1 | O277: 1 | P277: 1 | Q277: 2 | R277: 1 | S277: 0 | T277: 0 | U277: 0 | V277: 5 | W277: 2 | X277: 1 | Y277: 1 | Z277: 0 | AA277: 1 | AB277: 3
A278: =A277+1 -> 261 | B278: 29.19 | E278: 0 | F278: 1 | G278: 0 | H278: 1 | I278: 0 | J278: 1 | K278: 1 | L278: 0 | M278: 0 | N278: 1 | O278: 1 | P278: 2 | Q278: 2 | R278: 1 | S278: 1 | T278: 0 | U278: 4 | V278: 0 | W278: 0 | X278: 0 | Y278: 0 | Z278: 1 | AA278: 3 | AB278: 2
A279: =A278+1 -> 262 | B279: 29.27 | E279: 0 | F279: 0 | G279: 2 | H279: 1 | I279: 0 | J279: 0 | K279: 1 | L279: 1 | M279: 2 | N279: 0 | O279: 3 | P279: 0 | Q279: 3 | R279: 1 | S279: 0 | T279: 1 | U279: 1 | V279: 0 | W279: 1 | X279: 1 | Y279: 0 | Z279: 2 | AA279: 0 | AB279: 0
A280: =A279+1 -> 263 | B280: 29.34 | E280: 0 | F280: 1 | G280: 1 | H280: 1 | I280: 0 | J280: 2 | K280: 0 | L280: 1 | M280: 2 | N280: 0 | O280: 3 | P280: 0 | Q280: 2 | R280: 0 | S280: 0 | T280: 0 | U280: 5 | V280: 2 | W280: 1 | X280: 2 | Y280: 1 | Z280: 0 | AA280: 3 | AB280: 1
A281: =A280+1 -> 264 | B281: 29.42 | E281: 0 | F281: 0 | G281: 0 | H281: 0 | I281: 2 | J281: 3 | K281: 0 | L281: 1 | M281: 3 | N281: 0 | O281: 1 | P281: 0 | Q281: 2 | R281: 0 | S281: 1 | T281: 0 | U281: 3 | V281: 0 | W281: 2 | X281: 0 | Y281: 3 | Z281: 2 | AA281: 4 | AB281: 0
A282: =A281+1 -> 265 | B282: 29.5 | E282: 0 | F282: 1 | G282: 0 | H282: 1 | I282: 1 | J282: 0 | K282: 0 | L282: 0 | M282: 3 | N282: 0 | O282: 1 | P282: 0 | Q282: 1 | R282: 2 | S282: 0 | T282: 0 | U282: 4 | V282: 1 | W282: 0 | X282: 0 | Y282: 0 | Z282: 1 | AA282: 1 | AB282: 0
A283: =A282+1 -> 266 | B283: 29.58 | E283: 0 | F283: 0 | G283: 2 | H283: 2 | I283: 0 | J283: 1 | K283: 0 | L283: 1 | M283: 2 | N283: 0 | O283: 2 | P283: 1 | Q283: 2 | R283: 0 | S283: 0 | T283: 0 | U283: 2 | V283: 2 | W283: 1 | X283: 0 | Y283: 0 | Z283: 0 | AA283: 0 | AB283: 0
A284: =A283+1 -> 267 | B284: 29.65 | E284: 0 | F284: 2 | G284: 0 | H284: 1 | I284: 3 | J284: 0 | K284: 0 | L284: 0 | M284: 0 | N284: 1 | O284: 1 | P284: 1 | Q284: 2 | R284: 1 | S284: 1 | T284: 0 | U284: 4 | V284: 0 | W284: 0 | X284: 0 | Y284: 0 | Z284: 1 | AA284: 0 | AB284: 1
... A417: =A416+1 -> 400 | B417: 39.96 | E417: 0 | F417: 0 | G417: 1 | H417: 0 | I417: 0 | J417: 0 | K417: 0 | L417: 0 | M417: 0 | N417: 0 | O417: 1 | P417: 0 | Q417: 1 | R417: 1 | S417: 1 | T417: 0 | U417: 0 | V417: 0 | W417: 0 | X417: 0 | Y417: 1 | Z417: 2 | AA417: 1 | AB417: 0
A419: row 48 | B419: Cutt-off | E419: =SUM(E48:E417) -> 315 | F419: =SUM(F48:F417) -> 365 | G419: =SUM(G48:G417) -> 663 | H419: =SUM(H48:H417) -> 828 | I419: =SUM(I48:I417) -> 502 | J419: =SUM(J48:J417) -> 374 | K419: =SUM(K48:K417) -> 330 | L419: =SUM(L48:L417) -> 434 | ... AB419: =SUM(AB48:AB417) -> 507

Sheet 2. Initial grafic

Sheet 3. Calculate data
B4: Dilutionfactor | D4: =10.8/0.8 -> 13.5 | E4: x
B5: Counting volume | D5: 0.5 | E5: mL
D9: ='1. Add data'!C9 -> Blind | E9: ='1. Add data'!D9 -> Blind | F9: ='1. Add data'!E9 -> A1 | G9: ='1. Add data'!F9 -> B1 | H9: ='1. Add data'!G9 -> C1 | I9: ='1. Add data'!H9 -> D1 | J9: ='1. Add data'!I9 -> A2 | K9: ='1. Add data'!J9 -> B2 | ... AC9: ='1. Add data'!AB9 -> D6
B11: Sum | D11: =SUM('1. Add data'!C18:C273) -> 0 | E11: =SUM('1. Add data'!D18:D273) -> 0 | F11: =SUM('1. Add data'!E18:E273) -> 442 | G11: =SUM('1. Add data'!F18:F273) -> 485 | H11: =SUM('1. Add data'!G18:G273) -> 767 | I11: =SUM('1. Add data'!H18:H273) -> 959 | J11: =SUM('1. Add data'!I18:I273) -> 562 | K11: =SUM('1. Add data'!J18:J273) -> 450 | ... AC11: =SUM('1. Add data'!AB18:AB273) -> 561
B13: Total | D13: =D11*$D$4*(1/$D$5) -> 0 | E13: =E11*$D$4*(1/$D$5) -> 0 | F13: =F11*$D$4*(1/$D$5) -> 11934 | G13: =G11*$D$4*(1/$D$5) -> 13095 | H13: =H11*$D$4*(1/$D$5) -> 20709 | I13: =I11*$D$4*(1/$D$5) -> 25893 | J13: =J11*$D$4*(1/$D$5) -> 15174 | K13: =K11*$D$4*(1/$D$5) -> 12150 | ... AC13: =AC11*$D$4*(1/$D$5) -> 15147
C15: > mm
B16: Sum | C16: 11.36 | D16: =SUM('1. Add data'!C48:C417) -> 0 | E16: =SUM('1. Add data'!D48:D417) -> 0 | F16: =SUM('1. Add data'!E48:E417) -> 315 | G16: =SUM('1. Add data'!F48:F417) -> 365 | H16: =SUM('1. Add data'!G48:G417) -> 663 | I16: =SUM('1. Add data'!H48:H417) -> 828 | J16: =SUM('1. Add data'!I48:I417) -> 502 | K16: =SUM('1. Add data'!J48:J417) -> 374 | ... AC16: =SUM('1. Add data'!AB48:AB417) -> 507
B18: Total | C18: =C16 -> 11.36 | D18: =D16*$D$4*(1/$D$5) -> 0 | E18: =E16*$D$4*(1/$D$5) -> 0 | F18: =F16*$D$4*(1/$D$5) -> 8505 | G18: =G16*$D$4*(1/$D$5) -> 9855 | H18: =H16*$D$4*(1/$D$5) -> 17901 | I18: =I16*$D$4*(1/$D$5) -> 22356 | J18: =J16*$D$4*(1/$D$5) -> 13554 | K18: =K16*$D$4*(1/$D$5) -> 10098 | ... AC18: =AC16*$D$4*(1/$D$5) -> 13689
B20: Sum - blind | C20: =C16 -> 11.36 | E20: =AVERAGE(D18:E18) -> 0 | F20: =F18-$E$20 -> 8505 | G20: =G18-$E$20 -> 9855 | H20: =H18-$E$20 -> 17901 | I20: =I18-$E$20 -> 22356 | J20: =J18-$E$20 -> 13554 | K20: =K18-$E$20 -> 10098 | L20: =L18-$E$20 -> 8910 | M20: =M18-$E$20 -> 11718 | ... AC20: =AC18-$E$20 -> 13689
B22: MM Exp01 48h | D22: Kolonne
D23: 1 | F23: 2 | H23: 3 | J23: 4 | L23: 5 | N23: 6
B24: Middel | D24: =AVERAGE(F20:I20) -> 14654.25 | F24: =AVERAGE(J20:M20) -> 11070 | H24: =AVERAGE(N20:Q20) -> 20999.25 | J24: =AVERAGE(R20:U20) -> 18292.5 | L24: =AVERAGE(V20:Y20) -> 25447.5 | N24: =AVERAGE(Z20:AC20) -> 15147
B25: STD | D25: =STDEV(F20:I20) -> 6600.6165 | F25: =D25+STDEV(J20:M20) -> 8617.2593 | H25: =STDEV(N20:Q20) -> 8951.7488 | J25: =STDEV(R20:U20) -> 10252.549 | L25: =STDEV(V20:Y20) -> 16511.194 | N25: =STDEV(Z20:AC20) -> 1790.2989
B27: Relativ | D27: =D24/$D24*100 -> 100 | F27: =F24/$D24*100 -> 75.541225 | H27: =H24/$D24*100 -> 143.29802 | J27: =J24/$J24*100 -> 100 | L27: =L24/$J24*100 -> 139.11439 | N27: =N24/$J24*100 -> 82.804428
B28: Relativ STD | D28: =D25/$D24*100 -> 45.042336 | F28: =F25/$D24*100 -> 58.803823 | H28: =H25/$D24*100 -> 61.086366 | J28: =J25/$J24*100 -> 56.047826 | L28: =L25/$J24*100 -> 90.262094 | N28: =N25/$J24*100 -> 9.787065
C30: µM
B31: Cell number | C31: C1 | D31: =D24 -> 14654.25 | E31: =D25 -> 6600.6165
C32: C2 | D32: =F24 -> 11070 | E32: =F25 -> 8617.2593
C33: C3 | D33: =H24 -> 20999.25 | E33: =H25 -> 8951.7488
C34: C4 | D34: =J24 -> 18292.5 | E34: =J25 -> 10252.549
C35: C5 | D35: =L24 -> 25447.5 | E35: =L25 -> 16511.194
C36: C6 | D36: =N24 -> 15147 | E36: =N25 -> 1790.2989
D45: =C31 -> C1 | E45: =C32 -> C2 | F45: =C33 -> C3 | G45: =C34 -> C4 | H45: =C35 -> C5 | I45: =C36 -> C6
D46: =F20 -> 8505 | E46: =J20 -> 13554 | F46: =N20 -> 33291 | G46: =R20 -> 33372 | H46: =V20 -> 50112 | I46: =Z20 -> 15795
D47: =G20 -> 9855 | E47: =K20 -> 10098 | F47: =O20 -> 17280 | G47: =S20 -> 14796 | H47: =W20 -> 19062 | I47: =AA20 -> 17388
D48: =H20 -> 17901 | E48: =L20 -> 8910 | F48: =P20 -> 21114 | G48: =T20 -> 14580 | H48: =X20 -> 15390 | I48: =AB20 -> 13716
D49: =I20 -> 22356 | E49: =M20 -> 11718 | F49: =Q20 -> 12312 | G49: =U20 -> 10422 | H49: =Y20 -> 17226 | I49: =AC20 -> 13689
D54: =F20 -> 8505 | E54: =G20 -> 9855 | F54: =H20 -> 17901 | G54: =I20 -> 22356 | L54: =J20 -> 13554 | M54: =K20 -> 10098 | N54: =L20 -> 8910 | O54: =M20 -> 11718 | T54: =N20 -> 33291 | U54: =O20 -> 17280 | V54: =P20 -> 21114 | W54: =Q20 -> 12312 | AB54: =R20 -> 33372 | AC54: =S20 -> 14796 | AD54: =T20 -> 14580 | AE54: =U20 -> 10422 | AJ54: =V20 -> 50112 | AK54: =W20 -> 19062 | AL54: =X20 -> 15390 | AM54: =Y20 -> 17226 | AR54: =Z20 -> 15795 | AS54: =AA20 -> 17388 | AT54: =AB20 -> 13716 | AU54: =AC20 -> 13689

Sheet 4. Cummultative grafic

Sheet 5. 50% Cut off
H9: ='1. Add data'!E9 -> A1 | I9: ='1. Add data'!F9 -> B1 | J9: ='1. Add data'!G9 -> C1 | K9: ='1. Add data'!H9 -> D1 | L9: ='1. Add data'!I9 -> A2 | M9: ='1. Add data'!J9 -> B2 | N9: ='1. Add data'!K9 -> C2 | O9: ='1. Add data'!L9 -> D2 | ... AE9: ='1. Add data'!AB9 -> D6 | AI9: 1A-1D | AJ9: 2A-2D | AK9: 3A-3D | AL9: 4A-4D | AM9: 5A-5D | AN9: 6A-6D
A48: ='1. Add data'!A48 -> 31 | B48: ='1. Add data'!B48 -> 11.36 | H48: =H47+'1. Add data'!E48 -> 1 | I48: =I47+'1. Add data'!F48 -> 3 | J48: =J47+'1. Add data'!G48 -> 5 | K48: =K47+'1. Add data'!H48 -> 7 | L48: =L47+'1. Add data'!I48 -> 4 | M48: =M47+'1. Add data'!J48 -> 4 | N48: =N47+'1. Add data'!K48 -> 4 | O48: =O47+'1. Add data'!L48 -> 1 | ... AE48: =AE47+'1. Add data'!AB48 -> 2 | AI48: =AVERAGE(H48:K48) -> 4 | AJ48: =AVERAGE(L48:M48) -> 4 | AK48: =AVERAGE(P48:Q48) -> 5.5 | AL48: =AVERAGE(T48:U48) -> 2.5 | AM48: =AVERAGE(X48:Y48) -> 2 | AN48: =AVERAGE(AB48:AC48) -> 1
A49: ='1. Add data'!A49 -> 32 | B49: ='1. Add data'!B49 -> 11.44 | H49: =H48+'1. Add data'!E49 -> 2 | I49: =I48+'1. Add data'!F49 -> 6 | J49: =J48+'1. Add data'!G49 -> 9 | K49: =K48+'1. Add data'!H49 -> 12 | L49: =L48+'1. Add data'!I49 -> 7 | M49: =M48+'1. Add data'!J49 -> 7 | N49: =N48+'1. Add data'!K49 -> 7 | O49: =O48+'1. Add data'!L49 -> 3 | ... AE49: =AE48+'1. Add data'!AB49 -> 4 | AI49: =AVERAGE(H49:K49) -> 7.25 | AJ49: =AVERAGE(L49:M49) -> 7 | AK49: =AVERAGE(P49:Q49) -> 10 | AL49: =AVERAGE(T49:U49) -> 6 | AM49: =AVERAGE(X49:Y49) -> 5 | AN49: =AVERAGE(AB49:AC49) -> 2
A50: ='1. Add data'!A50 -> 33 | B50: ='1. Add data'!B50 -> 11.52 | H50: =H49+'1. Add data'!E50 -> 10 | I50: =I49+'1. Add data'!F50 -> 11 | J50: =J49+'1. Add data'!G50 -> 11 | K50: =K49+'1. Add data'!H50 -> 14 | L50: =L49+'1. Add data'!I50 -> 12 | M50: =M49+'1. Add data'!J50 -> 11 | N50: =N49+'1. Add data'!K50 -> 11 | O50: =O49+'1. Add data'!L50 -> 4 | ... AE50: =AE49+'1. Add data'!AB50 -> 7 | AI50: =AVERAGE(H50:K50) -> 11.5 | AJ50: =AVERAGE(L50:M50) -> 11.5 | AK50: =AVERAGE(P50:Q50) -> 14.5 | AL50: =AVERAGE(T50:U50) -> 9.5 | AM50: =AVERAGE(X50:Y50) -> 8.5 | AN50: =AVERAGE(AB50:AC50) -> 6
A51: ='1. Add data'!A51 -> 34 | B51: ='1. Add data'!B51 -> 11.6 | H51: =H50+'1. Add data'!E51 -> 10 | I51: =I50+'1. Add data'!F51 -> 15 | J51: =J50+'1. Add data'!G51 -> 13 | K51: =K50+'1. Add data'!H51 -> 17 | L51: =L50+'1. Add data'!I51 -> 14 | M51: =M50+'1. Add data'!J51 -> 15 | N51: =N50+'1. Add data'!K51 -> 13 | O51: =O50+'1. Add data'!L51 -> 8 | ... AE51: =AE50+'1. Add data'!AB51 -> 11 | AI51: =AVERAGE(H51:K51) -> 13.75 | AJ51: =AVERAGE(L51:M51) -> 14.5 | AK51: =AVERAGE(P51:Q51) -> 17.5 | AL51: =AVERAGE(T51:U51) -> 13 | AM51: =AVERAGE(X51:Y51) -> 12.5 | AN51: =AVERAGE(AB51:AC51) -> 8.5
A52: ='1. Add data'!A52 -> 35 | B52: ='1. Add data'!B52 -> 11.67 | H52: =H51+'1. Add data'!E52 -> 11 | I52: =I51+'1. Add data'!F52 -> 17 | J52: =J51+'1. Add data'!G52 -> 13 | K52: =K51+'1. Add data'!H52 -> 21 | L52: =L51+'1. Add data'!I52 -> 18 | M52: =M51+'1. Add data'!J52 -> 16 | N52: =N51+'1. Add data'!K52 -> 16 | O52: =O51+'1. Add data'!L52 -> 11 | ... AE52: =AE51+'1. Add data'!AB52 -> 15 | AI52: =AVERAGE(H52:K52) -> 15.5 | AJ52: =AVERAGE(L52:M52) -> 17 | AK52: =AVERAGE(P52:Q52) -> 19.5 | AL52: =AVERAGE(T52:U52) -> 16 | AM52: =AVERAGE(X52:Y52) -> 16 | AN52: =AVERAGE(AB52:AC52) -> 11.5
A53: ='1. Add data'!A53 -> 36 | B53: ='1. Add data'!B53 -> 11.75 | H53: =H52+'1. Add data'!E53 -> 12 | I53: =I52+'1. Add data'!F53 -> 20 | J53: =J52+'1. Add data'!G53 -> 17 | K53: =K52+'1. Add data'!H53 -> 27 | L53: =L52+'1. Add data'!I53 -> 20 | M53: =M52+'1. Add data'!J53 -> 17 | N53: =N52+'1. Add data'!K53 -> 21 | O53: =O52+'1. Add data'!L53 -> 13 | ... AE53: =AE52+'1. Add data'!AB53 -> 16 | AI53: =AVERAGE(H53:K53) -> 19 | AJ53: =AVERAGE(L53:M53) -> 18.5 | AK53: =AVERAGE(P53:Q53) -> 21.5 | AL53: =AVERAGE(T53:U53) -> 20.5 | AM53: =AVERAGE(X53:Y53) -> 19 | AN53: =AVERAGE(AB53:AC53) -> 14.5
A54: ='1. Add data'!A54 -> 37 | B54: ='1. Add data'!B54 -> 11.83 | H54: =H53+'1. Add data'!E54 -> 12 | I54: =I53+'1. Add data'!F54 -> 28 | J54: =J53+'1. Add data'!G54 -> 21 | K54: =K53+'1. Add data'!H54 -> 32 | L54: =L53+'1. Add data'!I54 -> 25 | M54: =M53+'1. Add data'!J54 -> 22 | N54: =N53+'1. Add data'!K54 -> 25 | O54: =O53+'1. Add data'!L54 -> 17 | ... AE54: =AE53+'1. Add data'!AB54 -> 16 | AI54: =AVERAGE(H54:K54) -> 23.25 | AJ54: =AVERAGE(L54:M54) -> 23.5 | AK54: =AVERAGE(P54:Q54) -> 25 | AL54: =AVERAGE(T54:U54) -> 24 | AM54: =AVERAGE(X54:Y54) -> 22.5 | AN54: =AVERAGE(AB54:AC54) -> 19.5
A55: ='1. Add data'!A55 -> 38 | B55: ='1. Add data'!B55 -> 11.91 | H55: =H54+'1. Add data'!E55 -> 14 | I55: =I54+'1. Add data'!F55 -> 33 | J55: =J54+'1. Add data'!G55 -> 24 | K55: =K54+'1. Add data'!H55 -> 35 | L55: =L54+'1. Add data'!I55 -> 28 | M55: =M54+'1. Add data'!J55 -> 22 | N55: =N54+'1. Add data'!K55 -> 28 | O55: =O54+'1. Add data'!L55 -> 22 | ... AE55: =AE54+'1. Add data'!AB55 -> 17 | AI55: =AVERAGE(H55:K55) -> 26.5 | AJ55: =AVERAGE(L55:M55) -> 25 | AK55: =AVERAGE(P55:Q55) -> 27.5 | AL55: =AVERAGE(T55:U55) -> 29 | AM55: =AVERAGE(X55:Y55) -> 25.5 | AN55: =AVERAGE(AB55:AC55) -> 21.5
A56: ='1. Add data'!A56 -> 39 | B56: ='1. Add data'!B56 -> 11.98 | H56: =H55+'1. Add data'!E56 -> 16 | I56: =I55+'1. Add data'!F56 -> 35 | J56: =J55+'1. Add data'!G56 -> 28 | K56: =K55+'1. Add data'!H56 -> 37 | L56: =L55+'1. Add data'!I56 -> 33 | M56: =M55+'1. Add data'!J56 -> 26 | N56: =N55+'1. Add data'!K56 -> 31 | O56: =O55+'1. Add data'!L56 -> 24 | ... AE56: =AE55+'1. Add data'!AB56 -> 18 | AI56: =AVERAGE(H56:K56) -> 29 | AJ56: =AVERAGE(L56:M56) -> 29.5 | AK56: =AVERAGE(P56:Q56) -> 30 | AL56: =AVERAGE(T56:U56) -> 32.5 | AM56: =AVERAGE(X56:Y56) -> 29 | AN56: =AVERAGE(AB56:AC56) -> 24.5
A57: ='1. Add data'!A57 -> 40 | B57: ='1. Add data'!B57 -> 12.06 | H57: =H56+'1. Add data'!E57 -> 18 | I57: =I56+'1. Add data'!F57 -> 38 | J57: =J56+'1. Add data'!G57 -> 34 | K57: =K56+'1. Add data'!H57 -> 41 | L57: =L56+'1. Add data'!I57 -> 38 | M57: =M56+'1. Add data'!J57 -> 26 | N57: =N56+'1. Add data'!K57 -> 35 | O57: =O56+'1. Add data'!L57 -> 26 | ... AE57: =AE56+'1. Add data'!AB57 -> 20 | AI57: =AVERAGE(H57:K57) -> 32.75 | AJ57: =AVERAGE(L57:M57) -> 32 | AK57: =AVERAGE(P57:Q57) -> 34 | AL57: =AVERAGE(T57:U57) -> 37 | AM57: =AVERAGE(X57:Y57) -> 33 | AN57: =AVERAGE(AB57:AC57) -> 26.5
A58: ='1. Add data'!A58 -> 41 | B58: ='1. Add data'!B58 -> 12.14 | H58: =H57+'1. Add data'!E58 -> 19 | I58: =I57+'1. Add data'!F58 -> 40 | J58: =J57+'1. Add data'!G58 -> 39 | K58: =K57+'1. Add data'!H58 -> 48 | L58: =L57+'1. Add data'!I58 -> 42 | M58: =M57+'1. Add data'!J58 -> 30 | N58: =N57+'1. Add data'!K58 -> 36 | O58: =O57+'1. Add data'!L58 -> 29 | ... AE58: =AE57+'1. Add data'!AB58 -> 25 | AI58: =AVERAGE(H58:K58) -> 36.5 | AJ58: =AVERAGE(L58:M58) -> 36 | AK58: =AVERAGE(P58:Q58) -> 39.5 | AL58: =AVERAGE(T58:U58) -> 43 | AM58: =AVERAGE(X58:Y58) -> 37 | AN58: =AVERAGE(AB58:AC58) -> 28
A59: ='1. Add data'!A59 -> 42 | B59: ='1. Add data'!B59 -> 12.22 | H59: =H58+'1. Add data'!E59 -> 19 | I59: =I58+'1. Add data'!F59 -> 41 | J59: =J58+'1. Add data'!G59 -> 43 | K59: =K58+'1. Add data'!H59 -> 53 | L59: =L58+'1. Add data'!I59 -> 43 | M59: =M58+'1. Add data'!J59 -> 31 | N59: =N58+'1. Add data'!K59 -> 39 | O59: =O58+'1. Add data'!L59 -> 32 | ... AE59: =AE58+'1. Add data'!AB59 -> 28 | AI59: =AVERAGE(H59:K59) -> 39 | AJ59: =AVERAGE(L59:M59) -> 37 | AK59: =AVERAGE(P59:Q59) -> 41 | AL59: =AVERAGE(T59:U59) -> 47 | AM59: =AVERAGE(X59:Y59) -> 41 | AN59: =AVERAGE(AB59:AC59) -> 28.5
... A417: ='1. Add data'!A417 -> 400 | B417: ='1. Add data'!B417 -> 39.96 | H417: =H416+'1. Add data'!E417 -> 315 | I417: =I416+'1. Add data'!F417 -> 365 | J417: =J416+'1. Add data'!G417 -> 663 | K417: =K416+'1. Add data'!H417 -> 828 | L417: =L416+'1. Add data'!I417 -> 502 | M417: =M416+'1. Add data'!J417 -> 374 | N417: =N416+'1. Add data'!K417 -> 330 | O417: =O416+'1. Add data'!L417 -> 434 | ... AE417: =AE416+'1. Add data'!AB417 -> 507 | AI417: =AVERAGE(H417:K417) -> 542.75 | AJ417: =AVERAGE(L417:M417) -> 438 | AK417: =AVERAGE(P417:Q417) -> 936.5 | AL417: =AVERAGE(T417:U417) -> 892 | AM417: =AVERAGE(X417:Y417) -> 1281 | AN417: =AVERAGE(AB417:AC417) -> 614.5
H419: ='1. Add data'!E419 -> 315 | I419: ='1. Add data'!F419 -> 365 | J419: ='1. Add data'!G419 -> 663 | K419: ='1. Add data'!H419 -> 828 | L419: ='1. Add data'!I419 -> 502 | M419: ='1. Add data'!J419 -> 374 | N419: ='1. Add data'!K419 -> 330 | O419: ='1. Add data'!L419 -> 434 | ... AE419: ='1. Add data'!AB419 -> 507
H421: =INDIRECT(ADDRESS(CELL("row",$G$425)+MATCH(50,H425:H670,1),CELL("col",$G$425))) -> 17.87 | I421: =INDIRECT(ADDRESS(CELL("row",$G$425)+MATCH(50,I425:I670,1),CELL("col",$G$425))) -> 17.56 | J421: =INDIRECT(ADDRESS(CELL("row",$G$425)+MATCH(50,J425:J670,1),CELL("col",$G$425))) -> 18.34 | K421: =INDIRECT(ADDRESS(CELL("row",$G$425)+MATCH(50,K425:K670,1),CELL("col",$G$425))) -> 18.8 | L421: =INDIRECT(ADDRESS(CELL("row",$G$425)+MATCH(50,L425:L670,1),CELL("col",$G$425))) -> 19.27 | M421: =INDIRECT(ADDRESS(CELL("row",$G$425)+MATCH(50,M425:M670,1),CELL("col",$G$425))) -> 19.11 | N421: =INDIRECT(ADDRESS(CELL("row",$G$425)+MATCH(50,N425:N670,1),CELL("col",$G$425))) -> 17.95 | O421: =INDIRECT(ADDRESS(CELL("row",$G$425)+MATCH(50,O425:O670,1),CELL("col",$G$425))) -> 19.27 | ... AE421: =INDIRECT(ADDRESS(CELL("row",$G$425)+MATCH(50,AE425:AE670,1),CELL("col",$G$425))) -> 23.07 | AI421: =C866 -> C1 | AJ421: =C867 -> C2 | AK421: =C868 -> C3 | AL421: =C869 -> C4 | AM421: =C870 -> C5 | AN421: =C871 -> C6
H422: =H9 -> A1 | I422: =I9 -> B1 | J422: =J9 -> C1 | K422: =K9 -> D1 | L422: =L9 -> A2 | M422: =M9 -> B2 | N422: =N9 -> C2 | O422: =O9 -> D2 | ... AE422: =AE9 -> D6
AH423: =G423 -> 0 | AI423: =AI24/AI$417 -> 0 | AJ423: =AJ24/AJ$417 -> 0 | AK423: =AK24/AK$417 -> 0 | AL423: =AL24/AL$417 -> 0 | AM423: =AM24/AM$417 -> 0 | AN423: =AN24/AN$417 -> 0
AH424: =G424 -> 0 | AI424: =AI25/AI$417 -> 0 | AJ424: =AJ25/AJ$417 -> 0 | AK424: =AK25/AK$417 -> 0 | AL424: =AL25/AL$417 -> 0 | AM424: =AM25/AM$417 -> 0 | AN424: =AN25/AN$417 -> 0
G425: =B26 -> 0 | H425: =H26/H$419*100 -> 0 | I425: =I26/I$419*100 -> 0 | J425: =J26/J$419*100 -> 0 | K425: =K26/K$419*100 -> 0 | L425: =L26/L$419*100 -> 0 | M425: =M26/M$419*100 -> 0 | N425: =N26/N$419*100 -> 0 | O425: =O26/O$419*100 -> 0 | ... AE425: =AE26/AE$419*100 -> 0 | AH425: =G425 -> 0 | AI425: =AI26/AI$417 -> 0 | AJ425: =AJ26/AJ$417 -> 0 | AK425: =AK26/AK$417 -> 0 | AL425: =AL26/AL$417 -> 0 | AM425: =AM26/AM$417 -> 0 | AN425: =AN26/AN$417 -> 0
G426: =B27 -> 0 | H426: =H27/H$419*100 -> 0 | I426: =I27/I$419*100 -> 0 | J426: =J27/J$419*100 -> 0 | K426: =K27/K$419*100 -> 0 | L426: =L27/L$419*100 -> 0 | M426: =M27/M$419*100 -> 0 | N426: =N27/N$419*100 -> 0 | O426: =O27/O$419*100 -> 0 | ... AE426: =AE27/AE$419*100 -> 0 | AH426: =G426 -> 0 | AI426: =AI27/AI$417 -> 0 | AJ426: =AJ27/AJ$417 -> 0 | AK426: =AK27/AK$417 -> 0 | AL426: =AL27/AL$417 -> 0 | AM426: =AM27/AM$417 -> 0 | AN426: =AN27/AN$417 -> 0
G427: =B28 -> 0 | H427: =H28/H$419*100 -> 0 | I427: =I28/I$419*100 -> 0 | J427: =J28/J$419*100 -> 0 | K427: =K28/K$419*100 -> 0 | L427: =L28/L$419*100 -> 0 | M427: =M28/M$419*100 -> 0 | N427: =N28/N$419*100 -> 0 | O427: =O28/O$419*100 -> 0 | ... AE427: =AE28/AE$419*100 -> 0 | AH427: =G427 -> 0 | AI427: =AI28/AI$417 -> 0 | AJ427: =AJ28/AJ$417 -> 0 | AK427: =AK28/AK$417 -> 0 | AL427: =AL28/AL$417 -> 0 | AM427: =AM28/AM$417 -> 0 | AN427: =AN28/AN$417 -> 0
G428: =B29 -> 0 | H428: =H29/H$419*100 -> 0 | I428: =I29/I$419*100 -> 0 | J428: =J29/J$419*100 -> 0 | K428: =K29/K$419*100 -> 0 | L428: =L29/L$419*100 -> 0 | M428: =M29/M$419*100 -> 0 | N428: =N29/N$419*100 -> 0 | O428: =O29/O$419*100 -> 0 | ... AE428: =AE29/AE$419*100 -> 0 | AH428: =G428 -> 0 | AI428: =AI29/AI$417 -> 0 | AJ428: =AJ29/AJ$417 -> 0 | AK428: =AK29/AK$417 -> 0 | AL428: =AL29/AL$417 -> 0 | AM428: =AM29/AM$417 -> 0 | AN428: =AN29/AN$417 -> 0
G429: =B30 -> 0 | H429: =H30/H$419*100 -> 0 | I429: =I30/I$419*100 -> 0 | J429: =J30/J$419*100 -> 0 | K429: =K30/K$419*100 -> 0 | L429: =L30/L$419*100 -> 0 | M429: =M30/M$419*100 -> 0 | N429: =N30/N$419*100 -> 0 | O429: =O30/O$419*100 -> 0 | ... AE429: =AE30/AE$419*100 -> 0 | AH429: =G429 -> 0 | AI429: =AI30/AI$417 -> 0 | AJ429: =AJ30/AJ$417 -> 0 | AK429: =AK30/AK$417 -> 0 | AL429: =AL30/AL$417 -> 0 | AM429: =AM30/AM$417 -> 0 | AN429: =AN30/AN$417 -> 0
G430: =B31 -> 0 | H430: =H31/H$419*100 -> 0 | I430: =I31/I$419*100 -> 0 | J430: =J31/J$419*100 -> 0 | K430: =K31/K$419*100 -> 0 | L430: =L31/L$419*100 -> 0 | M430: =M31/M$419*100 -> 0 | N430: =N31/N$419*100 -> 0 | O430: =O31/O$419*100 -> 0 | ... AE430: =AE31/AE$419*100 -> 0 | AH430: =G430 -> 0 | AI430: =AI31/AI$417 -> 0 | AJ430: =AJ31/AJ$417 -> 0 | AK430: =AK31/AK$417 -> 0 | AL430: =AL31/AL$417 -> 0 | AM430: =AM31/AM$417 -> 0 | AN430: =AN31/AN$417 -> 0
G431: =B32 -> 0 | H431: =H32/H$419*100 -> 0 | I431: =I32/I$419*100 -> 0 | J431: =J32/J$419*100 -> 0 | K431: =K32/K$419*100 -> 0 | L431: =L32/L$419*100 -> 0 | M431: =M32/M$419*100 -> 0 | N431: =N32/N$419*100 -> 0 | O431: =O32/O$419*100 -> 0 | ... AE431: =AE32/AE$419*100 -> 0 | AH431: =G431 -> 0 | AI431: =AI32/AI$417 -> 0 | AJ431: =AJ32/AJ$417 -> 0 | AK431: =AK32/AK$417 -> 0 | AL431: =AL32/AL$417 -> 0 | AM431: =AM32/AM$417 -> 0 | AN431: =AN32/AN$417 -> 0
G432: =B33 -> 0 | H432: =H33/H$419*100 -> 0 | I432: =I33/I$419*100 -> 0 | J432: =J33/J$419*100 -> 0 | K432: =K33/K$419*100 -> 0 | L432: =L33/L$419*100 -> 0 | M432: =M33/M$419*100 -> 0 | N432: =N33/N$419*100 -> 0 | O432: =O33/O$419*100 -> 0 | ... AE432: =AE33/AE$419*100 -> 0 | AH432: =G432 -> 0 | AI432: =AI33/AI$417 -> 0 | AJ432: =AJ33/AJ$417 -> 0 | AK432: =AK33/AK$417 -> 0 | AL432: =AL33/AL$417 -> 0 | AM432: =AM33/AM$417 -> 0 | AN432: =AN33/AN$417 -> 0
G433: =B34 -> 0 | H433: =H34/H$419*100 -> 0 | I433: =I34/I$419*100 -> 0 | J433: =J34/J$419*100 -> 0 | K433: =K34/K$419*100 -> 0 | L433: =L34/L$419*100 -> 0 | M433: =M34/M$419*100 -> 0 | N433: =N34/N$419*100 -> 0 | O433: =O34/O$419*100 -> 0 | ... AE433: =AE34/AE$419*100 -> 0 | AH433: =G433 -> 0 | AI433: =AI34/AI$417 -> 0 | AJ433: =AJ34/AJ$417 -> 0 | AK433: =AK34/AK$417 -> 0 | AL433: =AL34/AL$417 -> 0 | AM433: =AM34/AM$417 -> 0 | AN433: =AN34/AN$417 -> 0
G434: =B35 -> 0 | H434: =H35/H$419*100 -> 0 | I434: =I35/I$419*100 -> 0 | J434: =J35/J$419*100 -> 0 | K434: =K35/K$419*100 -> 0 | L434: =L35/L$419*100 -> 0 | M434: =M35/M$419*100 -> 0 | N434: =N35/N$419*100 -> 0 | O434: =O35/O$419*100 -> 0 | ... AE434: =AE35/AE$419*100 -> 0 | AH434: =G434 -> 0 | AI434: =AI35/AI$417 -> 0 | AJ434: =AJ35/AJ$417 -> 0 | AK434: =AK35/AK$417 -> 0 | AL434: =AL35/AL$417 -> 0 | AM434: =AM35/AM$417 -> 0 | AN434: =AN35/AN$417 -> 0
G435: =B36 -> 0 | H435: =H36/H$419*100 -> 0 | I435: =I36/I$419*100 -> 0 | J435: =J36/J$419*100 -> 0 | K435: =K36/K$419*100 -> 0 | L435: =L36/L$419*100 -> 0 | M435: =M36/M$419*100 -> 0 | N435: =N36/N$419*100 -> 0 | O435: =O36/O$419*100 -> 0 | ... AE435: =AE36/AE$419*100 -> 0 | AH435: =G435 -> 0 | AI435: =AI36/AI$417 -> 0 | AJ435: =AJ36/AJ$417 -> 0 | AK435: =AK36/AK$417 -> 0 | AL435: =AL36/AL$417 -> 0 | AM435: =AM36/AM$417 -> 0 | AN435: =AN36/AN$417 -> 0
G436: =B37 -> 0 | H436: =H37/H$419*100 -> 0 | I436: =I37/I$419*100 -> 0 | J436: =J37/J$419*100 -> 0 | K436: =K37/K$419*100 -> 0 | L436: =L37/L$419*100 -> 0 | M436: =M37/M$419*100 -> 0 | N436: =N37/N$419*100 -> 0 | O436: =O37/O$419*100 -> 0 | ... AE436: =AE37/AE$419*100 -> 0 | AH436: =G436 -> 0 | AI436: =AI37/AI$417 -> 0 | AJ436: =AJ37/AJ$417 -> 0 | AK436: =AK37/AK$417 -> 0 | AL436: =AL37/AL$417 -> 0 | AM436: =AM37/AM$417 -> 0 | AN436: =AN37/AN$417 -> 0
... G816: =B417 -> 39.96 | H816: =H417/H$419*100 -> 100 | I816: =I417/I$419*100 -> 100 | J816: =J417/J$419*100 -> 100 | K816: =K417/K$419*100 -> 100 | L816: =L417/L$419*100 -> 100 | M816: =M417/M$419*100 -> 100 | N816: =N417/N$419*100 -> 100 | O816: =O417/O$419*100 -> 100 | ... AE816: =AE417/AE$419*100 -> 100 | AH816: =G816 -> 39.96 | AI816: =AI417/AI$417 -> 1 | AJ816: =AJ417/AJ$417 -> 1 | AK816: =AK417/AK$417 -> 1 | AL816: =AL417/AL$417 -> 1 | AM816: =AM417/AM$417 -> 1 | AN816: =AN417/AN$417 -> 1
B821: ='3. Calculate data'!B22 -> MM Exp01 48h
B822: Cumultative relative cell number
B823: Cell diameter (µm)
B825: ='3. Calculate data'!J22 -> 0
B829: =B821 -> MM Exp01 48h
C830: A1 | D830: =H421 -> 17.87 | E830: =AVERAGE(D830:D833) -> 18.1425 | F830: =STDEV(D830:D833) -> 0.54310067
C831: B1 | D831: =I421 -> 17.56
C832: C1 | D832: =J421 -> 18.34
...

Sheet 6. Mean values
B16: µm | C16: C1 | D16: C2 | E16: C3 | F16: C4 | G16: C5 | H16: C6 | J16: µm
B18: ='1. Add data'!B18 -> 9.039 | C18: =AVERAGE('1. Add data'!E18:H18) -> 10.75 | D18: =AVERAGE('1. Add data'!I18:L18) -> 9.75 | E18: =AVERAGE('1. Add data'!M18:P18) -> 11.25 | F18: =AVERAGE('1. Add data'!Q18:T18) -> 7.75 | G18: =AVERAGE('1. Add data'!U18:X18) -> 9.25 | H18: =AVERAGE('1. Add data'!Y18:AB18) -> 5.25 | J18: =B18 -> 9.039 | K18: =C18/C$420*100 -> 1.469583 | L18: =D18/D$420*100 -> 1.7607223 | M18: =E18/E$420*100 -> 1.1814124 | N18: =F18/F$420*100 -> 0.91256991 | O18: =G18/G$420*100 -> 0.82295374 | P18: =H18/H$420*100 -> 0.7706422
B19: ='1. Add data'!B19 -> 9.116 | C19: =AVERAGE('1. Add data'!E19:H19) -> 12.25 | D19: =AVERAGE('1. Add data'!I19:L19) -> 7.75 | E19: =AVERAGE('1. Add data'!M19:P19) -> 8.75 | F19: =AVERAGE('1. Add data'!Q19:T19) -> 7.75 | G19: =AVERAGE('1. Add data'!U19:X19) -> 9.75 | H19: =AVERAGE('1. Add data'!Y19:AB19) -> 5 | J19: =B19 -> 9.116 | K19: =C19/C$420*100 -> 1.6746411 | L19: =D19/D$420*100 -> 1.3995485 | M19: =E19/E$420*100 -> 0.91887635 | N19: =F19/F$420*100 -> 0.91256991 | O19: =G19/G$420*100 -> 0.86743772 | P19: =H19/H$420*100 -> 0.73394495
B20: ='1. Add data'!B20 -> 9.194 | C20: =AVERAGE('1. Add data'!E20:H20) -> 12.25 | D20: =AVERAGE('1. Add data'!I20:L20) -> 6.25 | E20: =AVERAGE('1. Add data'!M20:P20) -> 8 | F20: =AVERAGE('1. Add data'!Q20:T20) -> 11 | G20: =AVERAGE('1. Add data'!U20:X20) -> 8.25 | H20: =AVERAGE('1. Add data'!Y20:AB20) -> 4.25 | J20: =B20 -> 9.194 | K20: =C20/C$420*100 -> 1.6746411 | L20: =D20/D$420*100 -> 1.1286682 | M20: =E20/E$420*100 -> 0.84011552 | N20: =F20/F$420*100 -> 1.2952605 | O20: =G20/G$420*100 -> 0.73398577 | P20: =H20/H$420*100 -> 0.62385321
B21: ='1. Add data'!B21 -> 9.271 | C21: =AVERAGE('1. Add data'!E21:H21) -> 9 | D21: =AVERAGE('1. Add data'!I21:L21) -> 8.5 | E21: =AVERAGE('1. Add data'!M21:P21) -> 10 | F21: =AVERAGE('1. Add data'!Q21:T21) -> 6.25 | G21: =AVERAGE('1. Add data'!U21:X21) -> 6 | H21: =AVERAGE('1. Add data'!Y21:AB21) -> 7 | J21: =B21 -> 9.271 | K21: =C21/C$420*100 -> 1.2303486 | L21: =D21/D$420*100 -> 1.5349887 | M21: =E21/E$420*100 -> 1.0501444 | N21: =F21/F$420*100 -> 0.73594348 | O21: =G21/G$420*100 -> 0.53380783 | P21: =H21/H$420*100 -> 1.0275229
B22: ='1. Add data'!B22 -> 9.349 | C22: =AVERAGE('1. Add data'!E22:H22) -> 8.5 | D22: =AVERAGE('1. Add data'!I22:L22) -> 7.75 | E22: =AVERAGE('1. Add data'!M22:P22) -> 8.5 | F22: =AVERAGE('1. Add data'!Q22:T22) -> 8.5 | G22: =AVERAGE('1. Add data'!U22:X22) -> 9.25 | H22: =AVERAGE('1. Add data'!Y22:AB22) -> 6.75 | J22: =B22 -> 9.349 | K22: =C22/C$420*100 -> 1.1619959 | L22: =D22/D$420*100 -> 1.3995485 | M22: =E22/E$420*100 -> 0.89262274 | N22: =F22/F$420*100 -> 1.0008831 | O22: =G22/G$420*100 -> 0.82295374 | P22: =H22/H$420*100 -> 0.99082569
B23: ='1. Add data'!B23 -> 9.426 | C23: =AVERAGE('1. Add data'!E23:H23) -> 7.5 | D23: =AVERAGE('1. Add data'!I23:L23) -> 6 | E23: =AVERAGE('1. Add data'!M23:P23) -> 8 | F23: =AVERAGE('1. Add data'!Q23:T23) -> 7.5 | G23: =AVERAGE('1. Add data'!U23:X23) -> 5.75 | H23: =AVERAGE('1. Add data'!Y23:AB23) -> 5.5 | J23: =B23 -> 9.426 | K23: =C23/C$420*100 -> 1.0252905 | L23: =D23/D$420*100 -> 1.0835214 | M23: =E23/E$420*100 -> 0.84011552 | N23: =F23/F$420*100 -> 0.88313218 | O23: =G23/G$420*100 -> 0.51156584 | P23: =H23/H$420*100 -> 0.80733945
B24: ='1. Add data'!B24 -> 9.504 | C24: =AVERAGE('1. Add data'!E24:H24) -> 9.25 | D24: =AVERAGE('1. Add data'!I24:L24) -> 8.5 | E24: =AVERAGE('1. Add data'!M24:P24) -> 7.75 | F24: =AVERAGE('1. Add data'!Q24:T24) -> 6 | G24: =AVERAGE('1. Add data'!U24:X24) -> 9.75 | H24: =AVERAGE('1. Add data'!Y24:AB24) -> 6.25 | J24: =B24 -> 9.504 | K24: =C24/C$420*100 -> 1.2645249 | L24: =D24/D$420*100 -> 1.5349887 | M24: =E24/E$420*100 -> 0.81386191 | N24: =F24/F$420*100 -> 0.70650574 | O24: =G24/G$420*100 -> 0.86743772 | P24: =H24/H$420*100 -> 0.91743119
B25: ='1. Add data'!B25 -> 9.581 | C25: =AVERAGE('1. Add data'!E25:H25) -> 9.5 | D25: =AVERAGE('1. Add data'!I25:L25) -> 6.75 | E25: =AVERAGE('1. Add data'!M25:P25) -> 8.25 | F25: =AVERAGE('1. Add data'!Q25:T25) -> 6.25 | G25: =AVERAGE('1. Add data'!U25:X25) -> 7 | H25: =AVERAGE('1. Add data'!Y25:AB25) -> 6 | J25: =B25 -> 9.581 | K25: =C25/C$420*100 -> 1.2987013 | L25: =D25/D$420*100 -> 1.2189616 | M25: =E25/E$420*100 -> 0.86636913 | N25: =F25/F$420*100 -> 0.73594348 | O25: =G25/G$420*100 -> 0.6227758 | P25: =H25/H$420*100 -> 0.88073394
B26: ='1. Add data'!B26 -> 9.659 | C26: =AVERAGE('1. Add data'!E26:H26) -> 9 | D26: =AVERAGE('1. Add data'!I26:L26) -> 4 | E26: =AVERAGE('1. Add data'!M26:P26) -> 4.5 | F26: =AVERAGE('1. Add data'!Q26:T26) -> 6.25 | G26: =AVERAGE('1. Add data'!U26:X26) -> 8 | H26: =AVERAGE('1. Add data'!Y26:AB26) -> 2.25 | J26: =B26 -> 9.659 | K26: =C26/C$420*100 -> 1.2303486 | L26: =D26/D$420*100 -> 0.72234763 | M26: =E26/E$420*100 -> 0.47256498 | N26: =F26/F$420*100 -> 0.73594348 | O26: =G26/G$420*100 -> 0.71174377 | P26: =H26/H$420*100 -> 0.33027523
B27: ='1. Add data'!B27 -> 9.736 | C27: =AVERAGE('1. Add data'!E27:H27) -> 7.25 | D27: =AVERAGE('1. Add data'!I27:L27) -> 7 | E27: =AVERAGE('1. Add data'!M27:P27) -> 5.5 | F27: =AVERAGE('1. Add data'!Q27:T27) -> 6 | G27: =AVERAGE('1. Add data'!U27:X27) -> 5.75 | H27: =AVERAGE('1. Add data'!Y27:AB27) -> 5.5 | J27: =B27 -> 9.736 | K27: =C27/C$420*100 -> 0.99111415 | L27: =D27/D$420*100 -> 1.2641084 | M27: =E27/E$420*100 -> 0.57757942 | N27: =F27/F$420*100 -> 0.70650574 | O27: =G27/G$420*100 -> 0.51156584 | P27: =H27/H$420*100 -> 0.80733945
B28: ='1. Add data'!B28 -> 9.814 | C28: =AVERAGE('1. Add data'!E28:H28) -> 5.5 | D28: =AVERAGE('1. Add data'!I28:L28) -> 4.5 | E28: =AVERAGE('1. Add data'!M28:P28) -> 6 | F28: =AVERAGE('1. Add data'!Q28:T28) -> 6.25 | G28: =AVERAGE('1. Add data'!U28:X28) -> 5 | H28: =AVERAGE('1. Add data'!Y28:AB28) -> 4 | J28: =B28 -> 9.814 | K28: =C28/C$420*100 -> 0.7518797 | L28: =D28/D$420*100 -> 0.81264108 | M28: =E28/E$420*100 -> 0.63008664 | N28: =F28/F$420*100 -> 0.73594348 | O28: =G28/G$420*100 -> 0.44483986 | P28: =H28/H$420*100 -> 0.58715596
B29: ='1. Add data'!B29 -> 9.891 | C29: =AVERAGE('1. Add data'!E29:H29) -> 6.75 | D29: =AVERAGE('1. Add data'!I29:L29) -> 7.5 | E29: =AVERAGE('1. Add data'!M29:P29) -> 6.5 | F29: =AVERAGE('1. Add data'!Q29:T29) -> 5.25 | G29: =AVERAGE('1. Add data'!U29:X29) -> 6.25 | H29: =AVERAGE('1. Add data'!Y29:AB29) -> 4.25 | J29: =B29 -> 9.891 | K29: =C29/C$420*100 -> 0.92276145 | L29: =D29/D$420*100 -> 1.3544018 | M29: =E29/E$420*100 -> 0.68259386 | N29: =F29/F$420*100 -> 0.61819252 | O29: =G29/G$420*100 -> 0.55604982 | P29: =H29/H$420*100 -> 0.62385321
... B417: ='1. Add data'!B417 -> 39.96 | C417: =AVERAGE('1. Add data'!E417:H417) -> 0.25 | D417: =AVERAGE('1. Add data'!I417:L417) -> 0 | E417: =AVERAGE('1. Add data'!M417:P417) -> 0.25 | F417: =AVERAGE('1. Add data'!Q417:T417) -> 0.75 | G417: =AVERAGE('1. Add data'!U417:X417) -> 0 | H417: =AVERAGE('1. Add data'!Y417:AB417) -> 1 | J417: =B417 -> 39.96 | K417: =C417/C$420*100 -> 0.03417635 | L417: =D417/D$420*100 -> 0 | M417: =E417/E$420*100 -> 0.02625361 | N417: =F417/F$420*100 -> 0.088313218 | O417: =G417/G$420*100 -> 0 | P417: =H417/H$420*100 -> 0.14678899
C420: =SUM(C18:C417) -> 731.5 | D420: =SUM(D18:D417) -> 553.75 | E420: =SUM(E18:E417) -> 952.25 | F420: =SUM(F18:F417) -> 849.25 | G420: =SUM(G18:G417) -> 1124 | H420: =SUM(H18:H417) -> 681.25
